<?xml version="1.0"?>
<robot xmlns:xacro="http://www.ros.org/wiki/xacro">

    <xacro:macro name="dc_motor_nt"
                 params="motor_name nt_entry_name parent_link child_link joint_axis:=z gear_ratio:=1 encoder_ppr:=-1 friction:=-1 damping:=-1 *pose">
        <!-- <xacro:property name="params_yaml" value="$(find gazebo_ros_motors)/params/dc_motor.yaml"/> -->
        <xacro:property name="motor_param" value="${load_yaml(params_yaml)}"/>

        <joint name='${motor_name}' type='revolute'>
            <parent>${parent_link}</parent>
            <child>${child_link}</child>
            <xacro:insert_block name="pose"/>
            <axis>
                <xyz>${ "1" if joint_axis=="x" else "0"} ${"1" if joint_axis=="y" else "0"}
                    ${"1" if joint_axis=="z" else "0"}
                </xyz>
                <dynamics>
                    <friction>${friction if friction > 0 else motor_param['joint_friction']}</friction>
                    <damping>${damping if damping > 0 else motor_param['joint_damping']}</damping>
                </dynamics>
            </axis>
            <provideFeedback>true</provideFeedback>
        </joint>

        <plugin name="${motor_name}_plugin" filename="libgazebo_ros_dc_motor_nt_interface.so">
            <motor_shaft_joint>${motor_name}</motor_shaft_joint>
            <motor_wrench_frame>${child_link}</motor_wrench_frame>
            <command_topic>${motor_name}/command</command_topic>
            <velocity_topic>${motor_name}/velocity</velocity_topic>
            <encoder_topic>${motor_name}/encoder</encoder_topic>
            <current_topic>${motor_name}/current</current_topic>
            <supply_topic>${motor_name}/supply_voltage</supply_topic>
            <publish_encoder>${motor_param['publish_encoder']}</publish_encoder>
            <publish_velocity>${motor_param['publish_velocity']}</publish_velocity>
            <publish_current>${motor_param['publish_current']}</publish_current>
            <publish_motor_joint_state>${motor_param['publish_motor_joint_state']}</publish_motor_joint_state>
            <update_rate>${motor_param['update_rate']}</update_rate>
            <motor_nominal_voltage>${motor_param['motor_nominal_voltage']}</motor_nominal_voltage>
            <moment_of_inertia>${motor_param['moment_of_inertia']}</moment_of_inertia>
            <armature_damping_ratio>${motor_param['armature_damping_ratio']}</armature_damping_ratio>
            <electromotive_force_constant>${motor_param['electromotive_force_constant']}
            </electromotive_force_constant>
            <electric_resistance>${motor_param['electric_resistance']}</electric_resistance>
            <electric_inductance>${motor_param['electric_inductance']}</electric_inductance>
            <gear_ratio>${gear_ratio if gear_ratio != 1 else motor_param['gear_ratio']}</gear_ratio>
            <encoder_ppr>${encoder_ppr if encoder_ppr > 0 else motor_param['encoder_ppr']}</encoder_ppr>
            <nt_velocity_noise>${motor_param['nt_velocity_noise']}</nt_velocity_noise>
            <nt_table_entry>${nt_entry_name}</nt_table_entry>
            <rosDebugLevel>Debug</rosDebugLevel>
            <joint_axis>${joint_axis}</joint_axis>
        </plugin>

    </xacro:macro>

</robot>